{
 "cells": [
  {
   "cell_type": "code",
   "execution_count": 1,
   "id": "79ef2f21-7158-41e3-849d-911cf06742d8",
   "metadata": {},
   "outputs": [],
   "source": [
    "import os\n",
    "import time\n",
    "import numpy as np\n",
    "import pandas as pd\n",
    "\n",
    "import rasterio\n",
    "from affine import Affine\n",
    "\n",
    "import dask_gateway\n",
    "import dask.array as da\n",
    "import dask.dataframe as daf\n",
    "\n",
    "import planetary_computer as pc\n",
    "\n",
    "import xarray as xr\n",
    "import rioxarray as rioxr\n",
    "\n",
    "from joblib import load\n",
    "\n",
    "import raster_to_features as rm\n",
    "import data_sampling_workflow.sample_rasters as sr\n",
    "\n",
    "import matplotlib.pyplot as plt"
   ]
  },
  {
   "cell_type": "code",
   "execution_count": 2,
   "id": "46745b41-fab9-4ed1-ad22-a2bcdb5d6427",
   "metadata": {},
   "outputs": [],
   "source": [
    "n_workers = 16#36\n",
    "workers_sqrt = 4 #6"
   ]
  },
  {
   "cell_type": "code",
   "execution_count": 3,
   "id": "a099bcd8-9d41-4fb0-a5d8-ba82eb077f1a",
   "metadata": {},
   "outputs": [
    {
     "data": {
      "text/html": [
       "<div>\n",
       "    <div style=\"width: 24px; height: 24px; background-color: #e1e1e1; border: 3px solid #9D9D9D; border-radius: 5px; position: absolute;\"> </div>\n",
       "    <div style=\"margin-left: 48px;\">\n",
       "        <h3 style=\"margin-bottom: 0px;\">Client</h3>\n",
       "        <p style=\"color: #9D9D9D; margin-bottom: 0px;\">Client-0ba11a6d-4a80-11ed-87d6-cee9fa6e0973</p>\n",
       "        <table style=\"width: 100%; text-align: left;\">\n",
       "\n",
       "        <tr>\n",
       "        \n",
       "            <td style=\"text-align: left;\"><strong>Connection method:</strong> Cluster object</td>\n",
       "            <td style=\"text-align: left;\"><strong>Cluster type:</strong> dask_gateway.GatewayCluster</td>\n",
       "        \n",
       "        </tr>\n",
       "\n",
       "        \n",
       "            <tr>\n",
       "                <td style=\"text-align: left;\">\n",
       "                    <strong>Dashboard: </strong> <a href=\"https://pccompute.westeurope.cloudapp.azure.com/compute/services/dask-gateway/clusters/prod.56f301a5a39d427198d2c7b36515d5d5/status\" target=\"_blank\">https://pccompute.westeurope.cloudapp.azure.com/compute/services/dask-gateway/clusters/prod.56f301a5a39d427198d2c7b36515d5d5/status</a>\n",
       "                </td>\n",
       "                <td style=\"text-align: left;\"></td>\n",
       "            </tr>\n",
       "        \n",
       "\n",
       "        </table>\n",
       "\n",
       "        \n",
       "            <details>\n",
       "            <summary style=\"margin-bottom: 20px;\"><h3 style=\"display: inline;\">Cluster Info</h3></summary>\n",
       "            <div style='background-color: #f2f2f2; display: inline-block; padding: 10px; border: 1px solid #999999;'>\n",
       "  <h3>GatewayCluster</h3>\n",
       "  <ul>\n",
       "    <li><b>Name: </b>prod.56f301a5a39d427198d2c7b36515d5d5\n",
       "    <li><b>Dashboard: </b><a href='https://pccompute.westeurope.cloudapp.azure.com/compute/services/dask-gateway/clusters/prod.56f301a5a39d427198d2c7b36515d5d5/status' target='_blank'>https://pccompute.westeurope.cloudapp.azure.com/compute/services/dask-gateway/clusters/prod.56f301a5a39d427198d2c7b36515d5d5/status</a>\n",
       "  </ul>\n",
       "</div>\n",
       "\n",
       "            </details>\n",
       "        \n",
       "\n",
       "    </div>\n",
       "</div>"
      ],
      "text/plain": [
       "<Client: 'tls://10.244.55.14:8786' processes=0 threads=0, memory=0 B>"
      ]
     },
     "execution_count": 3,
     "metadata": {},
     "output_type": "execute_result"
    }
   ],
   "source": [
    "# initialize DASK cluster\n",
    "cluster = dask_gateway.GatewayCluster()\n",
    "cluster.scale(n_workers)\n",
    "\n",
    "client = cluster.get_client()\n",
    "client"
   ]
  },
  {
   "cell_type": "code",
   "execution_count": 4,
   "id": "f05a96e0-e827-4240-b9a1-91d1f848cd26",
   "metadata": {},
   "outputs": [],
   "source": [
    "#scene_ids = pd.read_csv(os.path.join(os.getcwd(),'temp','coastal_scenes_ids_2020.csv')).itemid#.loc[19:26]\n",
    "itemid = 'ca_m_3412037_ne_10_060_20200607'"
   ]
  },
  {
   "cell_type": "code",
   "execution_count": 5,
   "id": "bcfc8b07-b54b-4c3f-8382-fd5ab614f669",
   "metadata": {},
   "outputs": [
    {
     "name": "stdout",
     "output_type": "stream",
     "text": [
      "loaded model\n"
     ]
    }
   ],
   "source": [
    "# ---------------------------------------\n",
    "# open pre-trained random forest classifier\n",
    "rfc = load('spectral_rfc.joblib') \n",
    "print('loaded model')"
   ]
  },
  {
   "cell_type": "code",
   "execution_count": 6,
   "id": "d70e8858-4ed6-4d74-8b62-efd21cc7bdff",
   "metadata": {},
   "outputs": [],
   "source": [
    "# ---------------------------------------\n",
    "# access NAIP scene\n",
    "item = sr.get_item_from_id(itemid)   \n",
    "href = pc.sign(item.assets[\"image\"].href)\n",
    "\n",
    "# save dimensions\n",
    "y_n = item.properties['proj:shape'][0]\n",
    "x_n = item.properties['proj:shape'][1]\n",
    "\n",
    "# open raster as dask.DataArray\n",
    "raster = rioxr.open_rasterio(href, chunks={\"x\": int(x_n/workers_sqrt), \"y\":int(y_n/workers_sqrt)})       \n",
    "raster = raster.drop_vars(['spatial_ref','x','y'])\n",
    "\n",
    "# ---------------------------------------\n",
    "# make dask.DataFrame with pixels\n",
    "pixels = daf.from_array(raster.stack(z=(\"y\", \"x\")).drop_vars('z').T, \n",
    "                      chunksize = int(x_n*y_n/n_workers))\n",
    "\n",
    "# convert into int16 to calculate ndvi and ndwi\n",
    "pixels = pixels.astype('int16')\n",
    "pixels['ndvi'] = (pixels[3] - pixels[0])/(pixels[3] + pixels[0])\n",
    "pixels['ndwi'] = (pixels[1] - pixels[3])/(pixels[1] + pixels[3])\n",
    "\n",
    "# add column with pixel number (a static index)\n",
    "pixels['pix_n'] = daf.from_array(np.arange(0,x_n*y_n), chunksize = int(x_n*y_n/n_workers))\n",
    "\n",
    "# ---------------------------------------\n",
    "# remove water and low ndvi pixels\n",
    "not_water = pixels[pixels.ndwi < 0.3]\n",
    "is_veg = not_water[not_water.ndvi > 0.05]\n",
    "\n",
    "# ---------------------------------------\n",
    "# clean dataframe and add date features\n",
    "# keep copy of pixel # of vegetation pixels\n",
    "is_veg_index = is_veg.pix_n\n",
    "\n",
    "date = item.datetime\n",
    "kwargs = {'year' : date.year,\n",
    "         'month' : date.month,\n",
    "         'day_in_year' : sr.day_in_year(date.day, date.month, date.year)}\n",
    "is_veg = is_veg.assign(**kwargs)\n",
    "\n",
    "is_veg = is_veg.drop(['ndwi','pix_n'], axis=1)\n",
    "\n",
    "#is_veg.persist()"
   ]
  },
  {
   "cell_type": "code",
   "execution_count": 8,
   "id": "0fd04331-4ae3-42da-bc62-05c545ad0105",
   "metadata": {},
   "outputs": [
    {
     "name": "stderr",
     "output_type": "stream",
     "text": [
      "argument of type 'NoneType' is not iterable\n",
      "Traceback (most recent call last):\n",
      "  File \"/srv/conda/envs/notebook/lib/python3.10/site-packages/distributed/comm/tcp.py\", line 223, in read\n",
      "    frames_nbytes = await stream.read_bytes(fmt_size)\n",
      "tornado.iostream.StreamClosedError: Stream is closed\n",
      "\n",
      "During handling of the above exception, another exception occurred:\n",
      "\n",
      "Traceback (most recent call last):\n",
      "  File \"/srv/conda/envs/notebook/lib/python3.10/site-packages/distributed/utils.py\", line 799, in wrapper\n",
      "    return await func(*args, **kwargs)\n",
      "  File \"/srv/conda/envs/notebook/lib/python3.10/site-packages/distributed/client.py\", line 1427, in _handle_report\n",
      "    msgs = await self.scheduler_comm.comm.read()\n",
      "  File \"/srv/conda/envs/notebook/lib/python3.10/site-packages/distributed/comm/tcp.py\", line 239, in read\n",
      "    convert_stream_closed_error(self, e)\n",
      "  File \"/srv/conda/envs/notebook/lib/python3.10/site-packages/distributed/comm/tcp.py\", line 140, in convert_stream_closed_error\n",
      "    if \"UNKNOWN_CA\" in exc.reason:\n",
      "TypeError: argument of type 'NoneType' is not iterable\n",
      "2022-10-12 22:51:23,025 - tornado.application - ERROR - Exception in callback <bound method Client._heartbeat of <Client: 'tls://10.244.55.14:8786' processes=16 threads=16, memory=128.00 GiB>>\n",
      "Traceback (most recent call last):\n",
      "  File \"/srv/conda/envs/notebook/lib/python3.10/site-packages/tornado/ioloop.py\", line 905, in _run\n",
      "    return self.callback()\n",
      "  File \"/srv/conda/envs/notebook/lib/python3.10/site-packages/distributed/client.py\", line 1374, in _heartbeat\n",
      "    self.scheduler_comm.send({\"op\": \"heartbeat-client\"})\n",
      "  File \"/srv/conda/envs/notebook/lib/python3.10/site-packages/distributed/batched.py\", line 140, in send\n",
      "    raise CommClosedError(f\"Comm {self.comm!r} already closed.\")\n",
      "distributed.comm.core.CommClosedError: Comm <TLS (closed) Client->Scheduler local=tls://10.244.62.9:47624 remote=gateway://traefik-dhub-prod-dask-gateway.prod:80/prod.56f301a5a39d427198d2c7b36515d5d5> already closed.\n",
      "2022-10-12 22:51:28,024 - tornado.application - ERROR - Exception in callback <bound method Client._heartbeat of <Client: 'tls://10.244.55.14:8786' processes=16 threads=16, memory=128.00 GiB>>\n",
      "Traceback (most recent call last):\n",
      "  File \"/srv/conda/envs/notebook/lib/python3.10/site-packages/tornado/ioloop.py\", line 905, in _run\n",
      "    return self.callback()\n",
      "  File \"/srv/conda/envs/notebook/lib/python3.10/site-packages/distributed/client.py\", line 1374, in _heartbeat\n",
      "    self.scheduler_comm.send({\"op\": \"heartbeat-client\"})\n",
      "  File \"/srv/conda/envs/notebook/lib/python3.10/site-packages/distributed/batched.py\", line 140, in send\n",
      "    raise CommClosedError(f\"Comm {self.comm!r} already closed.\")\n",
      "distributed.comm.core.CommClosedError: Comm <TLS (closed) Client->Scheduler local=tls://10.244.62.9:47624 remote=gateway://traefik-dhub-prod-dask-gateway.prod:80/prod.56f301a5a39d427198d2c7b36515d5d5> already closed.\n",
      "2022-10-12 22:51:33,026 - tornado.application - ERROR - Exception in callback <bound method Client._heartbeat of <Client: 'tls://10.244.55.14:8786' processes=16 threads=16, memory=128.00 GiB>>\n",
      "Traceback (most recent call last):\n",
      "  File \"/srv/conda/envs/notebook/lib/python3.10/site-packages/tornado/ioloop.py\", line 905, in _run\n",
      "    return self.callback()\n",
      "  File \"/srv/conda/envs/notebook/lib/python3.10/site-packages/distributed/client.py\", line 1374, in _heartbeat\n",
      "    self.scheduler_comm.send({\"op\": \"heartbeat-client\"})\n",
      "  File \"/srv/conda/envs/notebook/lib/python3.10/site-packages/distributed/batched.py\", line 140, in send\n",
      "    raise CommClosedError(f\"Comm {self.comm!r} already closed.\")\n",
      "distributed.comm.core.CommClosedError: Comm <TLS (closed) Client->Scheduler local=tls://10.244.62.9:47624 remote=gateway://traefik-dhub-prod-dask-gateway.prod:80/prod.56f301a5a39d427198d2c7b36515d5d5> already closed.\n",
      "2022-10-12 22:51:38,025 - tornado.application - ERROR - Exception in callback <bound method Client._heartbeat of <Client: 'tls://10.244.55.14:8786' processes=16 threads=16, memory=128.00 GiB>>\n",
      "Traceback (most recent call last):\n",
      "  File \"/srv/conda/envs/notebook/lib/python3.10/site-packages/tornado/ioloop.py\", line 905, in _run\n",
      "    return self.callback()\n",
      "  File \"/srv/conda/envs/notebook/lib/python3.10/site-packages/distributed/client.py\", line 1374, in _heartbeat\n",
      "    self.scheduler_comm.send({\"op\": \"heartbeat-client\"})\n",
      "  File \"/srv/conda/envs/notebook/lib/python3.10/site-packages/distributed/batched.py\", line 140, in send\n",
      "    raise CommClosedError(f\"Comm {self.comm!r} already closed.\")\n",
      "distributed.comm.core.CommClosedError: Comm <TLS (closed) Client->Scheduler local=tls://10.244.62.9:47624 remote=gateway://traefik-dhub-prod-dask-gateway.prod:80/prod.56f301a5a39d427198d2c7b36515d5d5> already closed.\n",
      "2022-10-12 22:51:43,026 - tornado.application - ERROR - Exception in callback <bound method Client._heartbeat of <Client: 'tls://10.244.55.14:8786' processes=16 threads=16, memory=128.00 GiB>>\n",
      "Traceback (most recent call last):\n",
      "  File \"/srv/conda/envs/notebook/lib/python3.10/site-packages/tornado/ioloop.py\", line 905, in _run\n",
      "    return self.callback()\n",
      "  File \"/srv/conda/envs/notebook/lib/python3.10/site-packages/distributed/client.py\", line 1374, in _heartbeat\n",
      "    self.scheduler_comm.send({\"op\": \"heartbeat-client\"})\n",
      "  File \"/srv/conda/envs/notebook/lib/python3.10/site-packages/distributed/batched.py\", line 140, in send\n",
      "    raise CommClosedError(f\"Comm {self.comm!r} already closed.\")\n",
      "distributed.comm.core.CommClosedError: Comm <TLS (closed) Client->Scheduler local=tls://10.244.62.9:47624 remote=gateway://traefik-dhub-prod-dask-gateway.prod:80/prod.56f301a5a39d427198d2c7b36515d5d5> already closed.\n",
      "2022-10-12 22:51:48,025 - tornado.application - ERROR - Exception in callback <bound method Client._heartbeat of <Client: 'tls://10.244.55.14:8786' processes=16 threads=16, memory=128.00 GiB>>\n",
      "Traceback (most recent call last):\n",
      "  File \"/srv/conda/envs/notebook/lib/python3.10/site-packages/tornado/ioloop.py\", line 905, in _run\n",
      "    return self.callback()\n",
      "  File \"/srv/conda/envs/notebook/lib/python3.10/site-packages/distributed/client.py\", line 1374, in _heartbeat\n",
      "    self.scheduler_comm.send({\"op\": \"heartbeat-client\"})\n",
      "  File \"/srv/conda/envs/notebook/lib/python3.10/site-packages/distributed/batched.py\", line 140, in send\n",
      "    raise CommClosedError(f\"Comm {self.comm!r} already closed.\")\n",
      "distributed.comm.core.CommClosedError: Comm <TLS (closed) Client->Scheduler local=tls://10.244.62.9:47624 remote=gateway://traefik-dhub-prod-dask-gateway.prod:80/prod.56f301a5a39d427198d2c7b36515d5d5> already closed.\n",
      "2022-10-12 22:51:53,024 - tornado.application - ERROR - Exception in callback <bound method Client._heartbeat of <Client: 'tls://10.244.55.14:8786' processes=16 threads=16, memory=128.00 GiB>>\n",
      "Traceback (most recent call last):\n",
      "  File \"/srv/conda/envs/notebook/lib/python3.10/site-packages/tornado/ioloop.py\", line 905, in _run\n",
      "    return self.callback()\n",
      "  File \"/srv/conda/envs/notebook/lib/python3.10/site-packages/distributed/client.py\", line 1374, in _heartbeat\n",
      "    self.scheduler_comm.send({\"op\": \"heartbeat-client\"})\n",
      "  File \"/srv/conda/envs/notebook/lib/python3.10/site-packages/distributed/batched.py\", line 140, in send\n",
      "    raise CommClosedError(f\"Comm {self.comm!r} already closed.\")\n",
      "distributed.comm.core.CommClosedError: Comm <TLS (closed) Client->Scheduler local=tls://10.244.62.9:47624 remote=gateway://traefik-dhub-prod-dask-gateway.prod:80/prod.56f301a5a39d427198d2c7b36515d5d5> already closed.\n",
      "2022-10-12 22:51:58,025 - tornado.application - ERROR - Exception in callback <bound method Client._heartbeat of <Client: 'tls://10.244.55.14:8786' processes=16 threads=16, memory=128.00 GiB>>\n",
      "Traceback (most recent call last):\n",
      "  File \"/srv/conda/envs/notebook/lib/python3.10/site-packages/tornado/ioloop.py\", line 905, in _run\n",
      "    return self.callback()\n",
      "  File \"/srv/conda/envs/notebook/lib/python3.10/site-packages/distributed/client.py\", line 1374, in _heartbeat\n",
      "    self.scheduler_comm.send({\"op\": \"heartbeat-client\"})\n",
      "  File \"/srv/conda/envs/notebook/lib/python3.10/site-packages/distributed/batched.py\", line 140, in send\n",
      "    raise CommClosedError(f\"Comm {self.comm!r} already closed.\")\n",
      "distributed.comm.core.CommClosedError: Comm <TLS (closed) Client->Scheduler local=tls://10.244.62.9:47624 remote=gateway://traefik-dhub-prod-dask-gateway.prod:80/prod.56f301a5a39d427198d2c7b36515d5d5> already closed.\n",
      "2022-10-12 22:52:03,025 - tornado.application - ERROR - Exception in callback <bound method Client._heartbeat of <Client: 'tls://10.244.55.14:8786' processes=16 threads=16, memory=128.00 GiB>>\n",
      "Traceback (most recent call last):\n",
      "  File \"/srv/conda/envs/notebook/lib/python3.10/site-packages/tornado/ioloop.py\", line 905, in _run\n",
      "    return self.callback()\n",
      "  File \"/srv/conda/envs/notebook/lib/python3.10/site-packages/distributed/client.py\", line 1374, in _heartbeat\n",
      "    self.scheduler_comm.send({\"op\": \"heartbeat-client\"})\n",
      "  File \"/srv/conda/envs/notebook/lib/python3.10/site-packages/distributed/batched.py\", line 140, in send\n",
      "    raise CommClosedError(f\"Comm {self.comm!r} already closed.\")\n",
      "distributed.comm.core.CommClosedError: Comm <TLS (closed) Client->Scheduler local=tls://10.244.62.9:47624 remote=gateway://traefik-dhub-prod-dask-gateway.prod:80/prod.56f301a5a39d427198d2c7b36515d5d5> already closed.\n",
      "2022-10-12 22:52:08,025 - tornado.application - ERROR - Exception in callback <bound method Client._heartbeat of <Client: 'tls://10.244.55.14:8786' processes=16 threads=16, memory=128.00 GiB>>\n",
      "Traceback (most recent call last):\n",
      "  File \"/srv/conda/envs/notebook/lib/python3.10/site-packages/tornado/ioloop.py\", line 905, in _run\n",
      "    return self.callback()\n",
      "  File \"/srv/conda/envs/notebook/lib/python3.10/site-packages/distributed/client.py\", line 1374, in _heartbeat\n",
      "    self.scheduler_comm.send({\"op\": \"heartbeat-client\"})\n",
      "  File \"/srv/conda/envs/notebook/lib/python3.10/site-packages/distributed/batched.py\", line 140, in send\n",
      "    raise CommClosedError(f\"Comm {self.comm!r} already closed.\")\n",
      "distributed.comm.core.CommClosedError: Comm <TLS (closed) Client->Scheduler local=tls://10.244.62.9:47624 remote=gateway://traefik-dhub-prod-dask-gateway.prod:80/prod.56f301a5a39d427198d2c7b36515d5d5> already closed.\n",
      "2022-10-12 22:52:13,026 - tornado.application - ERROR - Exception in callback <bound method Client._heartbeat of <Client: 'tls://10.244.55.14:8786' processes=16 threads=16, memory=128.00 GiB>>\n",
      "Traceback (most recent call last):\n",
      "  File \"/srv/conda/envs/notebook/lib/python3.10/site-packages/tornado/ioloop.py\", line 905, in _run\n",
      "    return self.callback()\n",
      "  File \"/srv/conda/envs/notebook/lib/python3.10/site-packages/distributed/client.py\", line 1374, in _heartbeat\n",
      "    self.scheduler_comm.send({\"op\": \"heartbeat-client\"})\n",
      "  File \"/srv/conda/envs/notebook/lib/python3.10/site-packages/distributed/batched.py\", line 140, in send\n",
      "    raise CommClosedError(f\"Comm {self.comm!r} already closed.\")\n",
      "distributed.comm.core.CommClosedError: Comm <TLS (closed) Client->Scheduler local=tls://10.244.62.9:47624 remote=gateway://traefik-dhub-prod-dask-gateway.prod:80/prod.56f301a5a39d427198d2c7b36515d5d5> already closed.\n",
      "2022-10-12 22:52:18,025 - tornado.application - ERROR - Exception in callback <bound method Client._heartbeat of <Client: 'tls://10.244.55.14:8786' processes=16 threads=16, memory=128.00 GiB>>\n",
      "Traceback (most recent call last):\n",
      "  File \"/srv/conda/envs/notebook/lib/python3.10/site-packages/tornado/ioloop.py\", line 905, in _run\n",
      "    return self.callback()\n",
      "  File \"/srv/conda/envs/notebook/lib/python3.10/site-packages/distributed/client.py\", line 1374, in _heartbeat\n",
      "    self.scheduler_comm.send({\"op\": \"heartbeat-client\"})\n",
      "  File \"/srv/conda/envs/notebook/lib/python3.10/site-packages/distributed/batched.py\", line 140, in send\n",
      "    raise CommClosedError(f\"Comm {self.comm!r} already closed.\")\n",
      "distributed.comm.core.CommClosedError: Comm <TLS (closed) Client->Scheduler local=tls://10.244.62.9:47624 remote=gateway://traefik-dhub-prod-dask-gateway.prod:80/prod.56f301a5a39d427198d2c7b36515d5d5> already closed.\n",
      "2022-10-12 22:52:23,026 - tornado.application - ERROR - Exception in callback <bound method Client._heartbeat of <Client: 'tls://10.244.55.14:8786' processes=16 threads=16, memory=128.00 GiB>>\n",
      "Traceback (most recent call last):\n",
      "  File \"/srv/conda/envs/notebook/lib/python3.10/site-packages/tornado/ioloop.py\", line 905, in _run\n",
      "    return self.callback()\n",
      "  File \"/srv/conda/envs/notebook/lib/python3.10/site-packages/distributed/client.py\", line 1374, in _heartbeat\n",
      "    self.scheduler_comm.send({\"op\": \"heartbeat-client\"})\n",
      "  File \"/srv/conda/envs/notebook/lib/python3.10/site-packages/distributed/batched.py\", line 140, in send\n",
      "    raise CommClosedError(f\"Comm {self.comm!r} already closed.\")\n",
      "distributed.comm.core.CommClosedError: Comm <TLS (closed) Client->Scheduler local=tls://10.244.62.9:47624 remote=gateway://traefik-dhub-prod-dask-gateway.prod:80/prod.56f301a5a39d427198d2c7b36515d5d5> already closed.\n",
      "2022-10-12 22:52:28,024 - tornado.application - ERROR - Exception in callback <bound method Client._heartbeat of <Client: 'tls://10.244.55.14:8786' processes=16 threads=16, memory=128.00 GiB>>\n",
      "Traceback (most recent call last):\n",
      "  File \"/srv/conda/envs/notebook/lib/python3.10/site-packages/tornado/ioloop.py\", line 905, in _run\n",
      "    return self.callback()\n",
      "  File \"/srv/conda/envs/notebook/lib/python3.10/site-packages/distributed/client.py\", line 1374, in _heartbeat\n",
      "    self.scheduler_comm.send({\"op\": \"heartbeat-client\"})\n",
      "  File \"/srv/conda/envs/notebook/lib/python3.10/site-packages/distributed/batched.py\", line 140, in send\n",
      "    raise CommClosedError(f\"Comm {self.comm!r} already closed.\")\n",
      "distributed.comm.core.CommClosedError: Comm <TLS (closed) Client->Scheduler local=tls://10.244.62.9:47624 remote=gateway://traefik-dhub-prod-dask-gateway.prod:80/prod.56f301a5a39d427198d2c7b36515d5d5> already closed.\n",
      "2022-10-12 22:52:33,025 - tornado.application - ERROR - Exception in callback <bound method Client._heartbeat of <Client: 'tls://10.244.55.14:8786' processes=16 threads=16, memory=128.00 GiB>>\n",
      "Traceback (most recent call last):\n",
      "  File \"/srv/conda/envs/notebook/lib/python3.10/site-packages/tornado/ioloop.py\", line 905, in _run\n",
      "    return self.callback()\n",
      "  File \"/srv/conda/envs/notebook/lib/python3.10/site-packages/distributed/client.py\", line 1374, in _heartbeat\n",
      "    self.scheduler_comm.send({\"op\": \"heartbeat-client\"})\n",
      "  File \"/srv/conda/envs/notebook/lib/python3.10/site-packages/distributed/batched.py\", line 140, in send\n",
      "    raise CommClosedError(f\"Comm {self.comm!r} already closed.\")\n",
      "distributed.comm.core.CommClosedError: Comm <TLS (closed) Client->Scheduler local=tls://10.244.62.9:47624 remote=gateway://traefik-dhub-prod-dask-gateway.prod:80/prod.56f301a5a39d427198d2c7b36515d5d5> already closed.\n",
      "2022-10-12 22:52:38,025 - tornado.application - ERROR - Exception in callback <bound method Client._heartbeat of <Client: 'tls://10.244.55.14:8786' processes=16 threads=16, memory=128.00 GiB>>\n",
      "Traceback (most recent call last):\n",
      "  File \"/srv/conda/envs/notebook/lib/python3.10/site-packages/tornado/ioloop.py\", line 905, in _run\n",
      "    return self.callback()\n",
      "  File \"/srv/conda/envs/notebook/lib/python3.10/site-packages/distributed/client.py\", line 1374, in _heartbeat\n",
      "    self.scheduler_comm.send({\"op\": \"heartbeat-client\"})\n",
      "  File \"/srv/conda/envs/notebook/lib/python3.10/site-packages/distributed/batched.py\", line 140, in send\n",
      "    raise CommClosedError(f\"Comm {self.comm!r} already closed.\")\n",
      "distributed.comm.core.CommClosedError: Comm <TLS (closed) Client->Scheduler local=tls://10.244.62.9:47624 remote=gateway://traefik-dhub-prod-dask-gateway.prod:80/prod.56f301a5a39d427198d2c7b36515d5d5> already closed.\n",
      "2022-10-12 22:52:43,025 - tornado.application - ERROR - Exception in callback <bound method Client._heartbeat of <Client: 'tls://10.244.55.14:8786' processes=16 threads=16, memory=128.00 GiB>>\n",
      "Traceback (most recent call last):\n",
      "  File \"/srv/conda/envs/notebook/lib/python3.10/site-packages/tornado/ioloop.py\", line 905, in _run\n",
      "    return self.callback()\n",
      "  File \"/srv/conda/envs/notebook/lib/python3.10/site-packages/distributed/client.py\", line 1374, in _heartbeat\n",
      "    self.scheduler_comm.send({\"op\": \"heartbeat-client\"})\n",
      "  File \"/srv/conda/envs/notebook/lib/python3.10/site-packages/distributed/batched.py\", line 140, in send\n",
      "    raise CommClosedError(f\"Comm {self.comm!r} already closed.\")\n",
      "distributed.comm.core.CommClosedError: Comm <TLS (closed) Client->Scheduler local=tls://10.244.62.9:47624 remote=gateway://traefik-dhub-prod-dask-gateway.prod:80/prod.56f301a5a39d427198d2c7b36515d5d5> already closed.\n",
      "2022-10-12 22:52:48,024 - tornado.application - ERROR - Exception in callback <bound method Client._heartbeat of <Client: 'tls://10.244.55.14:8786' processes=16 threads=16, memory=128.00 GiB>>\n",
      "Traceback (most recent call last):\n",
      "  File \"/srv/conda/envs/notebook/lib/python3.10/site-packages/tornado/ioloop.py\", line 905, in _run\n",
      "    return self.callback()\n",
      "  File \"/srv/conda/envs/notebook/lib/python3.10/site-packages/distributed/client.py\", line 1374, in _heartbeat\n",
      "    self.scheduler_comm.send({\"op\": \"heartbeat-client\"})\n",
      "  File \"/srv/conda/envs/notebook/lib/python3.10/site-packages/distributed/batched.py\", line 140, in send\n",
      "    raise CommClosedError(f\"Comm {self.comm!r} already closed.\")\n",
      "distributed.comm.core.CommClosedError: Comm <TLS (closed) Client->Scheduler local=tls://10.244.62.9:47624 remote=gateway://traefik-dhub-prod-dask-gateway.prod:80/prod.56f301a5a39d427198d2c7b36515d5d5> already closed.\n",
      "2022-10-12 22:52:53,026 - tornado.application - ERROR - Exception in callback <bound method Client._heartbeat of <Client: 'tls://10.244.55.14:8786' processes=16 threads=16, memory=128.00 GiB>>\n",
      "Traceback (most recent call last):\n",
      "  File \"/srv/conda/envs/notebook/lib/python3.10/site-packages/tornado/ioloop.py\", line 905, in _run\n",
      "    return self.callback()\n",
      "  File \"/srv/conda/envs/notebook/lib/python3.10/site-packages/distributed/client.py\", line 1374, in _heartbeat\n",
      "    self.scheduler_comm.send({\"op\": \"heartbeat-client\"})\n",
      "  File \"/srv/conda/envs/notebook/lib/python3.10/site-packages/distributed/batched.py\", line 140, in send\n",
      "    raise CommClosedError(f\"Comm {self.comm!r} already closed.\")\n",
      "distributed.comm.core.CommClosedError: Comm <TLS (closed) Client->Scheduler local=tls://10.244.62.9:47624 remote=gateway://traefik-dhub-prod-dask-gateway.prod:80/prod.56f301a5a39d427198d2c7b36515d5d5> already closed.\n",
      "2022-10-12 22:52:58,024 - tornado.application - ERROR - Exception in callback <bound method Client._heartbeat of <Client: 'tls://10.244.55.14:8786' processes=16 threads=16, memory=128.00 GiB>>\n",
      "Traceback (most recent call last):\n",
      "  File \"/srv/conda/envs/notebook/lib/python3.10/site-packages/tornado/ioloop.py\", line 905, in _run\n",
      "    return self.callback()\n",
      "  File \"/srv/conda/envs/notebook/lib/python3.10/site-packages/distributed/client.py\", line 1374, in _heartbeat\n",
      "    self.scheduler_comm.send({\"op\": \"heartbeat-client\"})\n",
      "  File \"/srv/conda/envs/notebook/lib/python3.10/site-packages/distributed/batched.py\", line 140, in send\n",
      "    raise CommClosedError(f\"Comm {self.comm!r} already closed.\")\n",
      "distributed.comm.core.CommClosedError: Comm <TLS (closed) Client->Scheduler local=tls://10.244.62.9:47624 remote=gateway://traefik-dhub-prod-dask-gateway.prod:80/prod.56f301a5a39d427198d2c7b36515d5d5> already closed.\n",
      "2022-10-12 22:53:03,025 - tornado.application - ERROR - Exception in callback <bound method Client._heartbeat of <Client: 'tls://10.244.55.14:8786' processes=16 threads=16, memory=128.00 GiB>>\n",
      "Traceback (most recent call last):\n",
      "  File \"/srv/conda/envs/notebook/lib/python3.10/site-packages/tornado/ioloop.py\", line 905, in _run\n",
      "    return self.callback()\n",
      "  File \"/srv/conda/envs/notebook/lib/python3.10/site-packages/distributed/client.py\", line 1374, in _heartbeat\n",
      "    self.scheduler_comm.send({\"op\": \"heartbeat-client\"})\n",
      "  File \"/srv/conda/envs/notebook/lib/python3.10/site-packages/distributed/batched.py\", line 140, in send\n",
      "    raise CommClosedError(f\"Comm {self.comm!r} already closed.\")\n",
      "distributed.comm.core.CommClosedError: Comm <TLS (closed) Client->Scheduler local=tls://10.244.62.9:47624 remote=gateway://traefik-dhub-prod-dask-gateway.prod:80/prod.56f301a5a39d427198d2c7b36515d5d5> already closed.\n",
      "2022-10-12 22:53:08,024 - tornado.application - ERROR - Exception in callback <bound method Client._heartbeat of <Client: 'tls://10.244.55.14:8786' processes=16 threads=16, memory=128.00 GiB>>\n",
      "Traceback (most recent call last):\n",
      "  File \"/srv/conda/envs/notebook/lib/python3.10/site-packages/tornado/ioloop.py\", line 905, in _run\n",
      "    return self.callback()\n",
      "  File \"/srv/conda/envs/notebook/lib/python3.10/site-packages/distributed/client.py\", line 1374, in _heartbeat\n",
      "    self.scheduler_comm.send({\"op\": \"heartbeat-client\"})\n",
      "  File \"/srv/conda/envs/notebook/lib/python3.10/site-packages/distributed/batched.py\", line 140, in send\n",
      "    raise CommClosedError(f\"Comm {self.comm!r} already closed.\")\n",
      "distributed.comm.core.CommClosedError: Comm <TLS (closed) Client->Scheduler local=tls://10.244.62.9:47624 remote=gateway://traefik-dhub-prod-dask-gateway.prod:80/prod.56f301a5a39d427198d2c7b36515d5d5> already closed.\n",
      "2022-10-12 22:53:13,025 - tornado.application - ERROR - Exception in callback <bound method Client._heartbeat of <Client: 'tls://10.244.55.14:8786' processes=16 threads=16, memory=128.00 GiB>>\n",
      "Traceback (most recent call last):\n",
      "  File \"/srv/conda/envs/notebook/lib/python3.10/site-packages/tornado/ioloop.py\", line 905, in _run\n",
      "    return self.callback()\n",
      "  File \"/srv/conda/envs/notebook/lib/python3.10/site-packages/distributed/client.py\", line 1374, in _heartbeat\n",
      "    self.scheduler_comm.send({\"op\": \"heartbeat-client\"})\n",
      "  File \"/srv/conda/envs/notebook/lib/python3.10/site-packages/distributed/batched.py\", line 140, in send\n",
      "    raise CommClosedError(f\"Comm {self.comm!r} already closed.\")\n",
      "distributed.comm.core.CommClosedError: Comm <TLS (closed) Client->Scheduler local=tls://10.244.62.9:47624 remote=gateway://traefik-dhub-prod-dask-gateway.prod:80/prod.56f301a5a39d427198d2c7b36515d5d5> already closed.\n",
      "2022-10-12 22:53:18,025 - tornado.application - ERROR - Exception in callback <bound method Client._heartbeat of <Client: 'tls://10.244.55.14:8786' processes=16 threads=16, memory=128.00 GiB>>\n",
      "Traceback (most recent call last):\n",
      "  File \"/srv/conda/envs/notebook/lib/python3.10/site-packages/tornado/ioloop.py\", line 905, in _run\n",
      "    return self.callback()\n",
      "  File \"/srv/conda/envs/notebook/lib/python3.10/site-packages/distributed/client.py\", line 1374, in _heartbeat\n",
      "    self.scheduler_comm.send({\"op\": \"heartbeat-client\"})\n",
      "  File \"/srv/conda/envs/notebook/lib/python3.10/site-packages/distributed/batched.py\", line 140, in send\n",
      "    raise CommClosedError(f\"Comm {self.comm!r} already closed.\")\n",
      "distributed.comm.core.CommClosedError: Comm <TLS (closed) Client->Scheduler local=tls://10.244.62.9:47624 remote=gateway://traefik-dhub-prod-dask-gateway.prod:80/prod.56f301a5a39d427198d2c7b36515d5d5> already closed.\n",
      "2022-10-12 22:53:23,025 - tornado.application - ERROR - Exception in callback <bound method Client._heartbeat of <Client: 'tls://10.244.55.14:8786' processes=16 threads=16, memory=128.00 GiB>>\n",
      "Traceback (most recent call last):\n",
      "  File \"/srv/conda/envs/notebook/lib/python3.10/site-packages/tornado/ioloop.py\", line 905, in _run\n",
      "    return self.callback()\n",
      "  File \"/srv/conda/envs/notebook/lib/python3.10/site-packages/distributed/client.py\", line 1374, in _heartbeat\n",
      "    self.scheduler_comm.send({\"op\": \"heartbeat-client\"})\n",
      "  File \"/srv/conda/envs/notebook/lib/python3.10/site-packages/distributed/batched.py\", line 140, in send\n",
      "    raise CommClosedError(f\"Comm {self.comm!r} already closed.\")\n",
      "distributed.comm.core.CommClosedError: Comm <TLS (closed) Client->Scheduler local=tls://10.244.62.9:47624 remote=gateway://traefik-dhub-prod-dask-gateway.prod:80/prod.56f301a5a39d427198d2c7b36515d5d5> already closed.\n",
      "2022-10-12 22:53:28,025 - tornado.application - ERROR - Exception in callback <bound method Client._heartbeat of <Client: 'tls://10.244.55.14:8786' processes=16 threads=16, memory=128.00 GiB>>\n",
      "Traceback (most recent call last):\n",
      "  File \"/srv/conda/envs/notebook/lib/python3.10/site-packages/tornado/ioloop.py\", line 905, in _run\n",
      "    return self.callback()\n",
      "  File \"/srv/conda/envs/notebook/lib/python3.10/site-packages/distributed/client.py\", line 1374, in _heartbeat\n",
      "    self.scheduler_comm.send({\"op\": \"heartbeat-client\"})\n",
      "  File \"/srv/conda/envs/notebook/lib/python3.10/site-packages/distributed/batched.py\", line 140, in send\n",
      "    raise CommClosedError(f\"Comm {self.comm!r} already closed.\")\n",
      "distributed.comm.core.CommClosedError: Comm <TLS (closed) Client->Scheduler local=tls://10.244.62.9:47624 remote=gateway://traefik-dhub-prod-dask-gateway.prod:80/prod.56f301a5a39d427198d2c7b36515d5d5> already closed.\n",
      "2022-10-12 22:53:33,024 - tornado.application - ERROR - Exception in callback <bound method Client._heartbeat of <Client: 'tls://10.244.55.14:8786' processes=16 threads=16, memory=128.00 GiB>>\n",
      "Traceback (most recent call last):\n",
      "  File \"/srv/conda/envs/notebook/lib/python3.10/site-packages/tornado/ioloop.py\", line 905, in _run\n",
      "    return self.callback()\n",
      "  File \"/srv/conda/envs/notebook/lib/python3.10/site-packages/distributed/client.py\", line 1374, in _heartbeat\n",
      "    self.scheduler_comm.send({\"op\": \"heartbeat-client\"})\n",
      "  File \"/srv/conda/envs/notebook/lib/python3.10/site-packages/distributed/batched.py\", line 140, in send\n",
      "    raise CommClosedError(f\"Comm {self.comm!r} already closed.\")\n",
      "distributed.comm.core.CommClosedError: Comm <TLS (closed) Client->Scheduler local=tls://10.244.62.9:47624 remote=gateway://traefik-dhub-prod-dask-gateway.prod:80/prod.56f301a5a39d427198d2c7b36515d5d5> already closed.\n",
      "2022-10-12 22:53:38,024 - tornado.application - ERROR - Exception in callback <bound method Client._heartbeat of <Client: 'tls://10.244.55.14:8786' processes=16 threads=16, memory=128.00 GiB>>\n",
      "Traceback (most recent call last):\n",
      "  File \"/srv/conda/envs/notebook/lib/python3.10/site-packages/tornado/ioloop.py\", line 905, in _run\n",
      "    return self.callback()\n",
      "  File \"/srv/conda/envs/notebook/lib/python3.10/site-packages/distributed/client.py\", line 1374, in _heartbeat\n",
      "    self.scheduler_comm.send({\"op\": \"heartbeat-client\"})\n",
      "  File \"/srv/conda/envs/notebook/lib/python3.10/site-packages/distributed/batched.py\", line 140, in send\n",
      "    raise CommClosedError(f\"Comm {self.comm!r} already closed.\")\n",
      "distributed.comm.core.CommClosedError: Comm <TLS (closed) Client->Scheduler local=tls://10.244.62.9:47624 remote=gateway://traefik-dhub-prod-dask-gateway.prod:80/prod.56f301a5a39d427198d2c7b36515d5d5> already closed.\n",
      "2022-10-12 22:53:43,026 - tornado.application - ERROR - Exception in callback <bound method Client._heartbeat of <Client: 'tls://10.244.55.14:8786' processes=16 threads=16, memory=128.00 GiB>>\n",
      "Traceback (most recent call last):\n",
      "  File \"/srv/conda/envs/notebook/lib/python3.10/site-packages/tornado/ioloop.py\", line 905, in _run\n",
      "    return self.callback()\n",
      "  File \"/srv/conda/envs/notebook/lib/python3.10/site-packages/distributed/client.py\", line 1374, in _heartbeat\n",
      "    self.scheduler_comm.send({\"op\": \"heartbeat-client\"})\n",
      "  File \"/srv/conda/envs/notebook/lib/python3.10/site-packages/distributed/batched.py\", line 140, in send\n",
      "    raise CommClosedError(f\"Comm {self.comm!r} already closed.\")\n",
      "distributed.comm.core.CommClosedError: Comm <TLS (closed) Client->Scheduler local=tls://10.244.62.9:47624 remote=gateway://traefik-dhub-prod-dask-gateway.prod:80/prod.56f301a5a39d427198d2c7b36515d5d5> already closed.\n",
      "2022-10-12 22:53:48,025 - tornado.application - ERROR - Exception in callback <bound method Client._heartbeat of <Client: 'tls://10.244.55.14:8786' processes=16 threads=16, memory=128.00 GiB>>\n",
      "Traceback (most recent call last):\n",
      "  File \"/srv/conda/envs/notebook/lib/python3.10/site-packages/tornado/ioloop.py\", line 905, in _run\n",
      "    return self.callback()\n",
      "  File \"/srv/conda/envs/notebook/lib/python3.10/site-packages/distributed/client.py\", line 1374, in _heartbeat\n",
      "    self.scheduler_comm.send({\"op\": \"heartbeat-client\"})\n",
      "  File \"/srv/conda/envs/notebook/lib/python3.10/site-packages/distributed/batched.py\", line 140, in send\n",
      "    raise CommClosedError(f\"Comm {self.comm!r} already closed.\")\n",
      "distributed.comm.core.CommClosedError: Comm <TLS (closed) Client->Scheduler local=tls://10.244.62.9:47624 remote=gateway://traefik-dhub-prod-dask-gateway.prod:80/prod.56f301a5a39d427198d2c7b36515d5d5> already closed.\n",
      "2022-10-12 22:53:53,026 - tornado.application - ERROR - Exception in callback <bound method Client._heartbeat of <Client: 'tls://10.244.55.14:8786' processes=16 threads=16, memory=128.00 GiB>>\n",
      "Traceback (most recent call last):\n",
      "  File \"/srv/conda/envs/notebook/lib/python3.10/site-packages/tornado/ioloop.py\", line 905, in _run\n",
      "    return self.callback()\n",
      "  File \"/srv/conda/envs/notebook/lib/python3.10/site-packages/distributed/client.py\", line 1374, in _heartbeat\n",
      "    self.scheduler_comm.send({\"op\": \"heartbeat-client\"})\n",
      "  File \"/srv/conda/envs/notebook/lib/python3.10/site-packages/distributed/batched.py\", line 140, in send\n",
      "    raise CommClosedError(f\"Comm {self.comm!r} already closed.\")\n",
      "distributed.comm.core.CommClosedError: Comm <TLS (closed) Client->Scheduler local=tls://10.244.62.9:47624 remote=gateway://traefik-dhub-prod-dask-gateway.prod:80/prod.56f301a5a39d427198d2c7b36515d5d5> already closed.\n",
      "2022-10-12 22:53:57,944 - tornado.application - ERROR - Exception in callback functools.partial(<bound method Client._send_to_scheduler_safe of <Client: 'tls://10.244.55.14:8786' processes=16 threads=16, memory=128.00 GiB>>, {'op': 'client-releases-keys', 'keys': [\"('_predict-cebb1f49e273002cda5ceb71fc940ada', 3)\"], 'client': 'Client-0ba11a6d-4a80-11ed-87d6-cee9fa6e0973'})\n",
      "Traceback (most recent call last):\n",
      "  File \"/srv/conda/envs/notebook/lib/python3.10/site-packages/tornado/ioloop.py\", line 741, in _run_callback\n",
      "    ret = callback()\n",
      "  File \"/srv/conda/envs/notebook/lib/python3.10/site-packages/distributed/client.py\", line 1148, in _send_to_scheduler_safe\n",
      "    self.scheduler_comm.send(msg)\n",
      "  File \"/srv/conda/envs/notebook/lib/python3.10/site-packages/distributed/batched.py\", line 140, in send\n",
      "    raise CommClosedError(f\"Comm {self.comm!r} already closed.\")\n",
      "distributed.comm.core.CommClosedError: Comm <TLS (closed) Client->Scheduler local=tls://10.244.62.9:47624 remote=gateway://traefik-dhub-prod-dask-gateway.prod:80/prod.56f301a5a39d427198d2c7b36515d5d5> already closed.\n",
      "2022-10-12 22:53:57,950 - tornado.application - ERROR - Exception in callback functools.partial(<bound method Client._send_to_scheduler_safe of <Client: 'tls://10.244.55.14:8786' processes=16 threads=16, memory=128.00 GiB>>, {'op': 'client-releases-keys', 'keys': [\"('_predict-cebb1f49e273002cda5ceb71fc940ada', 9)\"], 'client': 'Client-0ba11a6d-4a80-11ed-87d6-cee9fa6e0973'})\n",
      "Traceback (most recent call last):\n",
      "  File \"/srv/conda/envs/notebook/lib/python3.10/site-packages/tornado/ioloop.py\", line 741, in _run_callback\n",
      "    ret = callback()\n",
      "  File \"/srv/conda/envs/notebook/lib/python3.10/site-packages/distributed/client.py\", line 1148, in _send_to_scheduler_safe\n",
      "    self.scheduler_comm.send(msg)\n",
      "  File \"/srv/conda/envs/notebook/lib/python3.10/site-packages/distributed/batched.py\", line 140, in send\n",
      "    raise CommClosedError(f\"Comm {self.comm!r} already closed.\")\n",
      "distributed.comm.core.CommClosedError: Comm <TLS (closed) Client->Scheduler local=tls://10.244.62.9:47624 remote=gateway://traefik-dhub-prod-dask-gateway.prod:80/prod.56f301a5a39d427198d2c7b36515d5d5> already closed.\n",
      "2022-10-12 22:53:57,951 - tornado.application - ERROR - Exception in callback functools.partial(<bound method Client._send_to_scheduler_safe of <Client: 'tls://10.244.55.14:8786' processes=16 threads=16, memory=128.00 GiB>>, {'op': 'client-releases-keys', 'keys': [\"('_predict-cebb1f49e273002cda5ceb71fc940ada', 15)\"], 'client': 'Client-0ba11a6d-4a80-11ed-87d6-cee9fa6e0973'})\n",
      "Traceback (most recent call last):\n",
      "  File \"/srv/conda/envs/notebook/lib/python3.10/site-packages/tornado/ioloop.py\", line 741, in _run_callback\n",
      "    ret = callback()\n",
      "  File \"/srv/conda/envs/notebook/lib/python3.10/site-packages/distributed/client.py\", line 1148, in _send_to_scheduler_safe\n",
      "    self.scheduler_comm.send(msg)\n",
      "  File \"/srv/conda/envs/notebook/lib/python3.10/site-packages/distributed/batched.py\", line 140, in send\n",
      "    raise CommClosedError(f\"Comm {self.comm!r} already closed.\")\n",
      "distributed.comm.core.CommClosedError: Comm <TLS (closed) Client->Scheduler local=tls://10.244.62.9:47624 remote=gateway://traefik-dhub-prod-dask-gateway.prod:80/prod.56f301a5a39d427198d2c7b36515d5d5> already closed.\n",
      "2022-10-12 22:53:57,957 - tornado.application - ERROR - Exception in callback functools.partial(<bound method Client._send_to_scheduler_safe of <Client: 'tls://10.244.55.14:8786' processes=16 threads=16, memory=128.00 GiB>>, {'op': 'client-releases-keys', 'keys': [\"('_predict-cebb1f49e273002cda5ceb71fc940ada', 12)\"], 'client': 'Client-0ba11a6d-4a80-11ed-87d6-cee9fa6e0973'})\n",
      "Traceback (most recent call last):\n",
      "  File \"/srv/conda/envs/notebook/lib/python3.10/site-packages/tornado/ioloop.py\", line 741, in _run_callback\n",
      "    ret = callback()\n",
      "  File \"/srv/conda/envs/notebook/lib/python3.10/site-packages/distributed/client.py\", line 1148, in _send_to_scheduler_safe\n",
      "    self.scheduler_comm.send(msg)\n",
      "  File \"/srv/conda/envs/notebook/lib/python3.10/site-packages/distributed/batched.py\", line 140, in send\n",
      "    raise CommClosedError(f\"Comm {self.comm!r} already closed.\")\n",
      "distributed.comm.core.CommClosedError: Comm <TLS (closed) Client->Scheduler local=tls://10.244.62.9:47624 remote=gateway://traefik-dhub-prod-dask-gateway.prod:80/prod.56f301a5a39d427198d2c7b36515d5d5> already closed.\n",
      "2022-10-12 22:53:58,025 - tornado.application - ERROR - Exception in callback functools.partial(<bound method Client._send_to_scheduler_safe of <Client: 'tls://10.244.55.14:8786' processes=16 threads=16, memory=128.00 GiB>>, {'op': 'client-releases-keys', 'keys': [\"('_predict-cebb1f49e273002cda5ceb71fc940ada', 1)\"], 'client': 'Client-0ba11a6d-4a80-11ed-87d6-cee9fa6e0973'})\n",
      "Traceback (most recent call last):\n",
      "  File \"/srv/conda/envs/notebook/lib/python3.10/site-packages/tornado/ioloop.py\", line 741, in _run_callback\n",
      "    ret = callback()\n",
      "  File \"/srv/conda/envs/notebook/lib/python3.10/site-packages/distributed/client.py\", line 1148, in _send_to_scheduler_safe\n",
      "    self.scheduler_comm.send(msg)\n",
      "  File \"/srv/conda/envs/notebook/lib/python3.10/site-packages/distributed/batched.py\", line 140, in send\n",
      "    raise CommClosedError(f\"Comm {self.comm!r} already closed.\")\n",
      "distributed.comm.core.CommClosedError: Comm <TLS (closed) Client->Scheduler local=tls://10.244.62.9:47624 remote=gateway://traefik-dhub-prod-dask-gateway.prod:80/prod.56f301a5a39d427198d2c7b36515d5d5> already closed.\n",
      "2022-10-12 22:53:58,042 - tornado.application - ERROR - Exception in callback functools.partial(<bound method Client._send_to_scheduler_safe of <Client: 'tls://10.244.55.14:8786' processes=16 threads=16, memory=128.00 GiB>>, {'op': 'client-releases-keys', 'keys': [\"('_predict-cebb1f49e273002cda5ceb71fc940ada', 4)\"], 'client': 'Client-0ba11a6d-4a80-11ed-87d6-cee9fa6e0973'})\n",
      "Traceback (most recent call last):\n",
      "  File \"/srv/conda/envs/notebook/lib/python3.10/site-packages/tornado/ioloop.py\", line 741, in _run_callback\n",
      "    ret = callback()\n",
      "  File \"/srv/conda/envs/notebook/lib/python3.10/site-packages/distributed/client.py\", line 1148, in _send_to_scheduler_safe\n",
      "    self.scheduler_comm.send(msg)\n",
      "  File \"/srv/conda/envs/notebook/lib/python3.10/site-packages/distributed/batched.py\", line 140, in send\n",
      "    raise CommClosedError(f\"Comm {self.comm!r} already closed.\")\n",
      "distributed.comm.core.CommClosedError: Comm <TLS (closed) Client->Scheduler local=tls://10.244.62.9:47624 remote=gateway://traefik-dhub-prod-dask-gateway.prod:80/prod.56f301a5a39d427198d2c7b36515d5d5> already closed.\n",
      "2022-10-12 22:53:58,053 - tornado.application - ERROR - Exception in callback functools.partial(<bound method Client._send_to_scheduler_safe of <Client: 'tls://10.244.55.14:8786' processes=16 threads=16, memory=128.00 GiB>>, {'op': 'client-releases-keys', 'keys': [\"('_predict-cebb1f49e273002cda5ceb71fc940ada', 7)\"], 'client': 'Client-0ba11a6d-4a80-11ed-87d6-cee9fa6e0973'})\n",
      "Traceback (most recent call last):\n",
      "  File \"/srv/conda/envs/notebook/lib/python3.10/site-packages/tornado/ioloop.py\", line 741, in _run_callback\n",
      "    ret = callback()\n",
      "  File \"/srv/conda/envs/notebook/lib/python3.10/site-packages/distributed/client.py\", line 1148, in _send_to_scheduler_safe\n",
      "    self.scheduler_comm.send(msg)\n",
      "  File \"/srv/conda/envs/notebook/lib/python3.10/site-packages/distributed/batched.py\", line 140, in send\n",
      "    raise CommClosedError(f\"Comm {self.comm!r} already closed.\")\n",
      "distributed.comm.core.CommClosedError: Comm <TLS (closed) Client->Scheduler local=tls://10.244.62.9:47624 remote=gateway://traefik-dhub-prod-dask-gateway.prod:80/prod.56f301a5a39d427198d2c7b36515d5d5> already closed.\n",
      "2022-10-12 22:53:58,097 - tornado.application - ERROR - Exception in callback functools.partial(<bound method Client._send_to_scheduler_safe of <Client: 'tls://10.244.55.14:8786' processes=16 threads=16, memory=128.00 GiB>>, {'op': 'client-releases-keys', 'keys': [\"('_predict-cebb1f49e273002cda5ceb71fc940ada', 13)\"], 'client': 'Client-0ba11a6d-4a80-11ed-87d6-cee9fa6e0973'})\n",
      "Traceback (most recent call last):\n",
      "  File \"/srv/conda/envs/notebook/lib/python3.10/site-packages/tornado/ioloop.py\", line 741, in _run_callback\n",
      "    ret = callback()\n",
      "  File \"/srv/conda/envs/notebook/lib/python3.10/site-packages/distributed/client.py\", line 1148, in _send_to_scheduler_safe\n",
      "    self.scheduler_comm.send(msg)\n",
      "  File \"/srv/conda/envs/notebook/lib/python3.10/site-packages/distributed/batched.py\", line 140, in send\n",
      "    raise CommClosedError(f\"Comm {self.comm!r} already closed.\")\n",
      "distributed.comm.core.CommClosedError: Comm <TLS (closed) Client->Scheduler local=tls://10.244.62.9:47624 remote=gateway://traefik-dhub-prod-dask-gateway.prod:80/prod.56f301a5a39d427198d2c7b36515d5d5> already closed.\n",
      "2022-10-12 22:53:58,144 - tornado.application - ERROR - Exception in callback functools.partial(<bound method Client._send_to_scheduler_safe of <Client: 'tls://10.244.55.14:8786' processes=16 threads=16, memory=128.00 GiB>>, {'op': 'client-releases-keys', 'keys': [\"('_predict-cebb1f49e273002cda5ceb71fc940ada', 10)\"], 'client': 'Client-0ba11a6d-4a80-11ed-87d6-cee9fa6e0973'})\n",
      "Traceback (most recent call last):\n",
      "  File \"/srv/conda/envs/notebook/lib/python3.10/site-packages/tornado/ioloop.py\", line 741, in _run_callback\n",
      "    ret = callback()\n",
      "  File \"/srv/conda/envs/notebook/lib/python3.10/site-packages/distributed/client.py\", line 1148, in _send_to_scheduler_safe\n",
      "    self.scheduler_comm.send(msg)\n",
      "  File \"/srv/conda/envs/notebook/lib/python3.10/site-packages/distributed/batched.py\", line 140, in send\n",
      "    raise CommClosedError(f\"Comm {self.comm!r} already closed.\")\n",
      "distributed.comm.core.CommClosedError: Comm <TLS (closed) Client->Scheduler local=tls://10.244.62.9:47624 remote=gateway://traefik-dhub-prod-dask-gateway.prod:80/prod.56f301a5a39d427198d2c7b36515d5d5> already closed.\n",
      "2022-10-12 22:53:58,145 - tornado.application - ERROR - Exception in callback functools.partial(<bound method Client._send_to_scheduler_safe of <Client: 'tls://10.244.55.14:8786' processes=16 threads=16, memory=128.00 GiB>>, {'op': 'client-releases-keys', 'keys': [\"('_predict-cebb1f49e273002cda5ceb71fc940ada', 16)\"], 'client': 'Client-0ba11a6d-4a80-11ed-87d6-cee9fa6e0973'})\n",
      "Traceback (most recent call last):\n",
      "  File \"/srv/conda/envs/notebook/lib/python3.10/site-packages/tornado/ioloop.py\", line 741, in _run_callback\n",
      "    ret = callback()\n",
      "  File \"/srv/conda/envs/notebook/lib/python3.10/site-packages/distributed/client.py\", line 1148, in _send_to_scheduler_safe\n",
      "    self.scheduler_comm.send(msg)\n",
      "  File \"/srv/conda/envs/notebook/lib/python3.10/site-packages/distributed/batched.py\", line 140, in send\n",
      "    raise CommClosedError(f\"Comm {self.comm!r} already closed.\")\n",
      "distributed.comm.core.CommClosedError: Comm <TLS (closed) Client->Scheduler local=tls://10.244.62.9:47624 remote=gateway://traefik-dhub-prod-dask-gateway.prod:80/prod.56f301a5a39d427198d2c7b36515d5d5> already closed.\n",
      "2022-10-12 22:53:58,147 - tornado.application - ERROR - Exception in callback functools.partial(<bound method Client._send_to_scheduler_safe of <Client: 'tls://10.244.55.14:8786' processes=16 threads=16, memory=128.00 GiB>>, {'op': 'client-releases-keys', 'keys': [\"('_predict-cebb1f49e273002cda5ceb71fc940ada', 2)\"], 'client': 'Client-0ba11a6d-4a80-11ed-87d6-cee9fa6e0973'})\n",
      "Traceback (most recent call last):\n",
      "  File \"/srv/conda/envs/notebook/lib/python3.10/site-packages/tornado/ioloop.py\", line 741, in _run_callback\n",
      "    ret = callback()\n",
      "  File \"/srv/conda/envs/notebook/lib/python3.10/site-packages/distributed/client.py\", line 1148, in _send_to_scheduler_safe\n",
      "    self.scheduler_comm.send(msg)\n",
      "  File \"/srv/conda/envs/notebook/lib/python3.10/site-packages/distributed/batched.py\", line 140, in send\n",
      "    raise CommClosedError(f\"Comm {self.comm!r} already closed.\")\n",
      "distributed.comm.core.CommClosedError: Comm <TLS (closed) Client->Scheduler local=tls://10.244.62.9:47624 remote=gateway://traefik-dhub-prod-dask-gateway.prod:80/prod.56f301a5a39d427198d2c7b36515d5d5> already closed.\n",
      "2022-10-12 22:53:58,174 - tornado.application - ERROR - Exception in callback functools.partial(<bound method Client._send_to_scheduler_safe of <Client: 'tls://10.244.55.14:8786' processes=16 threads=16, memory=128.00 GiB>>, {'op': 'client-releases-keys', 'keys': [\"('_predict-cebb1f49e273002cda5ceb71fc940ada', 8)\"], 'client': 'Client-0ba11a6d-4a80-11ed-87d6-cee9fa6e0973'})\n",
      "Traceback (most recent call last):\n",
      "  File \"/srv/conda/envs/notebook/lib/python3.10/site-packages/tornado/ioloop.py\", line 741, in _run_callback\n",
      "    ret = callback()\n",
      "  File \"/srv/conda/envs/notebook/lib/python3.10/site-packages/distributed/client.py\", line 1148, in _send_to_scheduler_safe\n",
      "    self.scheduler_comm.send(msg)\n",
      "  File \"/srv/conda/envs/notebook/lib/python3.10/site-packages/distributed/batched.py\", line 140, in send\n",
      "    raise CommClosedError(f\"Comm {self.comm!r} already closed.\")\n",
      "distributed.comm.core.CommClosedError: Comm <TLS (closed) Client->Scheduler local=tls://10.244.62.9:47624 remote=gateway://traefik-dhub-prod-dask-gateway.prod:80/prod.56f301a5a39d427198d2c7b36515d5d5> already closed.\n",
      "2022-10-12 22:53:58,211 - tornado.application - ERROR - Exception in callback <bound method Client._heartbeat of <Client: 'tls://10.244.55.14:8786' processes=16 threads=16, memory=128.00 GiB>>\n",
      "Traceback (most recent call last):\n",
      "  File \"/srv/conda/envs/notebook/lib/python3.10/site-packages/tornado/ioloop.py\", line 905, in _run\n",
      "    return self.callback()\n",
      "  File \"/srv/conda/envs/notebook/lib/python3.10/site-packages/distributed/client.py\", line 1374, in _heartbeat\n",
      "    self.scheduler_comm.send({\"op\": \"heartbeat-client\"})\n",
      "  File \"/srv/conda/envs/notebook/lib/python3.10/site-packages/distributed/batched.py\", line 140, in send\n",
      "    raise CommClosedError(f\"Comm {self.comm!r} already closed.\")\n",
      "distributed.comm.core.CommClosedError: Comm <TLS (closed) Client->Scheduler local=tls://10.244.62.9:47624 remote=gateway://traefik-dhub-prod-dask-gateway.prod:80/prod.56f301a5a39d427198d2c7b36515d5d5> already closed.\n",
      "2022-10-12 22:53:58,246 - tornado.application - ERROR - Exception in callback functools.partial(<bound method Client._send_to_scheduler_safe of <Client: 'tls://10.244.55.14:8786' processes=16 threads=16, memory=128.00 GiB>>, {'op': 'client-releases-keys', 'keys': [\"('_predict-cebb1f49e273002cda5ceb71fc940ada', 5)\"], 'client': 'Client-0ba11a6d-4a80-11ed-87d6-cee9fa6e0973'})\n",
      "Traceback (most recent call last):\n",
      "  File \"/srv/conda/envs/notebook/lib/python3.10/site-packages/tornado/ioloop.py\", line 741, in _run_callback\n",
      "    ret = callback()\n",
      "  File \"/srv/conda/envs/notebook/lib/python3.10/site-packages/distributed/client.py\", line 1148, in _send_to_scheduler_safe\n",
      "    self.scheduler_comm.send(msg)\n",
      "  File \"/srv/conda/envs/notebook/lib/python3.10/site-packages/distributed/batched.py\", line 140, in send\n",
      "    raise CommClosedError(f\"Comm {self.comm!r} already closed.\")\n",
      "distributed.comm.core.CommClosedError: Comm <TLS (closed) Client->Scheduler local=tls://10.244.62.9:47624 remote=gateway://traefik-dhub-prod-dask-gateway.prod:80/prod.56f301a5a39d427198d2c7b36515d5d5> already closed.\n",
      "2022-10-12 22:53:58,289 - tornado.application - ERROR - Exception in callback functools.partial(<bound method Client._send_to_scheduler_safe of <Client: 'tls://10.244.55.14:8786' processes=16 threads=16, memory=128.00 GiB>>, {'op': 'client-releases-keys', 'keys': [\"('_predict-cebb1f49e273002cda5ceb71fc940ada', 11)\"], 'client': 'Client-0ba11a6d-4a80-11ed-87d6-cee9fa6e0973'})\n",
      "Traceback (most recent call last):\n",
      "  File \"/srv/conda/envs/notebook/lib/python3.10/site-packages/tornado/ioloop.py\", line 741, in _run_callback\n",
      "    ret = callback()\n",
      "  File \"/srv/conda/envs/notebook/lib/python3.10/site-packages/distributed/client.py\", line 1148, in _send_to_scheduler_safe\n",
      "    self.scheduler_comm.send(msg)\n",
      "  File \"/srv/conda/envs/notebook/lib/python3.10/site-packages/distributed/batched.py\", line 140, in send\n",
      "    raise CommClosedError(f\"Comm {self.comm!r} already closed.\")\n",
      "distributed.comm.core.CommClosedError: Comm <TLS (closed) Client->Scheduler local=tls://10.244.62.9:47624 remote=gateway://traefik-dhub-prod-dask-gateway.prod:80/prod.56f301a5a39d427198d2c7b36515d5d5> already closed.\n",
      "2022-10-12 22:53:58,349 - tornado.application - ERROR - Exception in callback functools.partial(<bound method Client._send_to_scheduler_safe of <Client: 'tls://10.244.55.14:8786' processes=16 threads=16, memory=128.00 GiB>>, {'op': 'client-releases-keys', 'keys': [\"('_predict-cebb1f49e273002cda5ceb71fc940ada', 14)\"], 'client': 'Client-0ba11a6d-4a80-11ed-87d6-cee9fa6e0973'})\n",
      "Traceback (most recent call last):\n",
      "  File \"/srv/conda/envs/notebook/lib/python3.10/site-packages/tornado/ioloop.py\", line 741, in _run_callback\n",
      "    ret = callback()\n",
      "  File \"/srv/conda/envs/notebook/lib/python3.10/site-packages/distributed/client.py\", line 1148, in _send_to_scheduler_safe\n",
      "    self.scheduler_comm.send(msg)\n",
      "  File \"/srv/conda/envs/notebook/lib/python3.10/site-packages/distributed/batched.py\", line 140, in send\n",
      "    raise CommClosedError(f\"Comm {self.comm!r} already closed.\")\n",
      "distributed.comm.core.CommClosedError: Comm <TLS (closed) Client->Scheduler local=tls://10.244.62.9:47624 remote=gateway://traefik-dhub-prod-dask-gateway.prod:80/prod.56f301a5a39d427198d2c7b36515d5d5> already closed.\n",
      "2022-10-12 22:53:58,392 - tornado.application - ERROR - Exception in callback functools.partial(<bound method Client._send_to_scheduler_safe of <Client: 'tls://10.244.55.14:8786' processes=16 threads=16, memory=128.00 GiB>>, {'op': 'client-releases-keys', 'keys': [\"('_predict-cebb1f49e273002cda5ceb71fc940ada', 0)\"], 'client': 'Client-0ba11a6d-4a80-11ed-87d6-cee9fa6e0973'})\n",
      "Traceback (most recent call last):\n",
      "  File \"/srv/conda/envs/notebook/lib/python3.10/site-packages/tornado/ioloop.py\", line 741, in _run_callback\n",
      "    ret = callback()\n",
      "  File \"/srv/conda/envs/notebook/lib/python3.10/site-packages/distributed/client.py\", line 1148, in _send_to_scheduler_safe\n",
      "    self.scheduler_comm.send(msg)\n",
      "  File \"/srv/conda/envs/notebook/lib/python3.10/site-packages/distributed/batched.py\", line 140, in send\n",
      "    raise CommClosedError(f\"Comm {self.comm!r} already closed.\")\n",
      "distributed.comm.core.CommClosedError: Comm <TLS (closed) Client->Scheduler local=tls://10.244.62.9:47624 remote=gateway://traefik-dhub-prod-dask-gateway.prod:80/prod.56f301a5a39d427198d2c7b36515d5d5> already closed.\n",
      "2022-10-12 22:53:58,435 - tornado.application - ERROR - Exception in callback functools.partial(<bound method Client._send_to_scheduler_safe of <Client: 'tls://10.244.55.14:8786' processes=16 threads=16, memory=128.00 GiB>>, {'op': 'client-releases-keys', 'keys': [\"('_predict-cebb1f49e273002cda5ceb71fc940ada', 6)\"], 'client': 'Client-0ba11a6d-4a80-11ed-87d6-cee9fa6e0973'})\n",
      "Traceback (most recent call last):\n",
      "  File \"/srv/conda/envs/notebook/lib/python3.10/site-packages/tornado/ioloop.py\", line 741, in _run_callback\n",
      "    ret = callback()\n",
      "  File \"/srv/conda/envs/notebook/lib/python3.10/site-packages/distributed/client.py\", line 1148, in _send_to_scheduler_safe\n",
      "    self.scheduler_comm.send(msg)\n",
      "  File \"/srv/conda/envs/notebook/lib/python3.10/site-packages/distributed/batched.py\", line 140, in send\n",
      "    raise CommClosedError(f\"Comm {self.comm!r} already closed.\")\n",
      "distributed.comm.core.CommClosedError: Comm <TLS (closed) Client->Scheduler local=tls://10.244.62.9:47624 remote=gateway://traefik-dhub-prod-dask-gateway.prod:80/prod.56f301a5a39d427198d2c7b36515d5d5> already closed.\n"
     ]
    },
    {
     "ename": "KeyboardInterrupt",
     "evalue": "",
     "output_type": "error",
     "traceback": [
      "\u001b[0;31m---------------------------------------------------------------------------\u001b[0m",
      "\u001b[0;31mKeyboardInterrupt\u001b[0m                         Traceback (most recent call last)",
      "Cell \u001b[0;32mIn [8], line 3\u001b[0m\n\u001b[1;32m      1\u001b[0m \u001b[38;5;66;03m# compute predictions\u001b[39;00m\n\u001b[1;32m      2\u001b[0m scene_preds \u001b[38;5;241m=\u001b[39m rfc\u001b[38;5;241m.\u001b[39mpredict(is_veg\u001b[38;5;241m.\u001b[39mto_dask_array())\n\u001b[0;32m----> 3\u001b[0m scene_preds \u001b[38;5;241m=\u001b[39m \u001b[43mscene_preds\u001b[49m\u001b[38;5;241;43m.\u001b[39;49m\u001b[43mcompute\u001b[49m\u001b[43m(\u001b[49m\u001b[43m)\u001b[49m\n",
      "File \u001b[0;32m/srv/conda/envs/notebook/lib/python3.10/site-packages/dask/base.py:315\u001b[0m, in \u001b[0;36mDaskMethodsMixin.compute\u001b[0;34m(self, **kwargs)\u001b[0m\n\u001b[1;32m    291\u001b[0m \u001b[38;5;28;01mdef\u001b[39;00m \u001b[38;5;21mcompute\u001b[39m(\u001b[38;5;28mself\u001b[39m, \u001b[38;5;241m*\u001b[39m\u001b[38;5;241m*\u001b[39mkwargs):\n\u001b[1;32m    292\u001b[0m     \u001b[38;5;124;03m\"\"\"Compute this dask collection\u001b[39;00m\n\u001b[1;32m    293\u001b[0m \n\u001b[1;32m    294\u001b[0m \u001b[38;5;124;03m    This turns a lazy Dask collection into its in-memory equivalent.\u001b[39;00m\n\u001b[0;32m   (...)\u001b[0m\n\u001b[1;32m    313\u001b[0m \u001b[38;5;124;03m    dask.base.compute\u001b[39;00m\n\u001b[1;32m    314\u001b[0m \u001b[38;5;124;03m    \"\"\"\u001b[39;00m\n\u001b[0;32m--> 315\u001b[0m     (result,) \u001b[38;5;241m=\u001b[39m \u001b[43mcompute\u001b[49m\u001b[43m(\u001b[49m\u001b[38;5;28;43mself\u001b[39;49m\u001b[43m,\u001b[49m\u001b[43m \u001b[49m\u001b[43mtraverse\u001b[49m\u001b[38;5;241;43m=\u001b[39;49m\u001b[38;5;28;43;01mFalse\u001b[39;49;00m\u001b[43m,\u001b[49m\u001b[43m \u001b[49m\u001b[38;5;241;43m*\u001b[39;49m\u001b[38;5;241;43m*\u001b[39;49m\u001b[43mkwargs\u001b[49m\u001b[43m)\u001b[49m\n\u001b[1;32m    316\u001b[0m     \u001b[38;5;28;01mreturn\u001b[39;00m result\n",
      "File \u001b[0;32m/srv/conda/envs/notebook/lib/python3.10/site-packages/dask/base.py:598\u001b[0m, in \u001b[0;36mcompute\u001b[0;34m(traverse, optimize_graph, scheduler, get, *args, **kwargs)\u001b[0m\n\u001b[1;32m    595\u001b[0m     keys\u001b[38;5;241m.\u001b[39mappend(x\u001b[38;5;241m.\u001b[39m__dask_keys__())\n\u001b[1;32m    596\u001b[0m     postcomputes\u001b[38;5;241m.\u001b[39mappend(x\u001b[38;5;241m.\u001b[39m__dask_postcompute__())\n\u001b[0;32m--> 598\u001b[0m results \u001b[38;5;241m=\u001b[39m \u001b[43mschedule\u001b[49m\u001b[43m(\u001b[49m\u001b[43mdsk\u001b[49m\u001b[43m,\u001b[49m\u001b[43m \u001b[49m\u001b[43mkeys\u001b[49m\u001b[43m,\u001b[49m\u001b[43m \u001b[49m\u001b[38;5;241;43m*\u001b[39;49m\u001b[38;5;241;43m*\u001b[39;49m\u001b[43mkwargs\u001b[49m\u001b[43m)\u001b[49m\n\u001b[1;32m    599\u001b[0m \u001b[38;5;28;01mreturn\u001b[39;00m repack([f(r, \u001b[38;5;241m*\u001b[39ma) \u001b[38;5;28;01mfor\u001b[39;00m r, (f, a) \u001b[38;5;129;01min\u001b[39;00m \u001b[38;5;28mzip\u001b[39m(results, postcomputes)])\n",
      "File \u001b[0;32m/srv/conda/envs/notebook/lib/python3.10/site-packages/distributed/client.py:3036\u001b[0m, in \u001b[0;36mClient.get\u001b[0;34m(self, dsk, keys, workers, allow_other_workers, resources, sync, asynchronous, direct, retries, priority, fifo_timeout, actors, **kwargs)\u001b[0m\n\u001b[1;32m   3034\u001b[0m         should_rejoin \u001b[38;5;241m=\u001b[39m \u001b[38;5;28;01mFalse\u001b[39;00m\n\u001b[1;32m   3035\u001b[0m \u001b[38;5;28;01mtry\u001b[39;00m:\n\u001b[0;32m-> 3036\u001b[0m     results \u001b[38;5;241m=\u001b[39m \u001b[38;5;28;43mself\u001b[39;49m\u001b[38;5;241;43m.\u001b[39;49m\u001b[43mgather\u001b[49m\u001b[43m(\u001b[49m\u001b[43mpacked\u001b[49m\u001b[43m,\u001b[49m\u001b[43m \u001b[49m\u001b[43masynchronous\u001b[49m\u001b[38;5;241;43m=\u001b[39;49m\u001b[43masynchronous\u001b[49m\u001b[43m,\u001b[49m\u001b[43m \u001b[49m\u001b[43mdirect\u001b[49m\u001b[38;5;241;43m=\u001b[39;49m\u001b[43mdirect\u001b[49m\u001b[43m)\u001b[49m\n\u001b[1;32m   3037\u001b[0m \u001b[38;5;28;01mfinally\u001b[39;00m:\n\u001b[1;32m   3038\u001b[0m     \u001b[38;5;28;01mfor\u001b[39;00m f \u001b[38;5;129;01min\u001b[39;00m futures\u001b[38;5;241m.\u001b[39mvalues():\n",
      "File \u001b[0;32m/srv/conda/envs/notebook/lib/python3.10/site-packages/distributed/client.py:2210\u001b[0m, in \u001b[0;36mClient.gather\u001b[0;34m(self, futures, errors, direct, asynchronous)\u001b[0m\n\u001b[1;32m   2208\u001b[0m \u001b[38;5;28;01melse\u001b[39;00m:\n\u001b[1;32m   2209\u001b[0m     local_worker \u001b[38;5;241m=\u001b[39m \u001b[38;5;28;01mNone\u001b[39;00m\n\u001b[0;32m-> 2210\u001b[0m \u001b[38;5;28;01mreturn\u001b[39;00m \u001b[38;5;28;43mself\u001b[39;49m\u001b[38;5;241;43m.\u001b[39;49m\u001b[43msync\u001b[49m\u001b[43m(\u001b[49m\n\u001b[1;32m   2211\u001b[0m \u001b[43m    \u001b[49m\u001b[38;5;28;43mself\u001b[39;49m\u001b[38;5;241;43m.\u001b[39;49m\u001b[43m_gather\u001b[49m\u001b[43m,\u001b[49m\n\u001b[1;32m   2212\u001b[0m \u001b[43m    \u001b[49m\u001b[43mfutures\u001b[49m\u001b[43m,\u001b[49m\n\u001b[1;32m   2213\u001b[0m \u001b[43m    \u001b[49m\u001b[43merrors\u001b[49m\u001b[38;5;241;43m=\u001b[39;49m\u001b[43merrors\u001b[49m\u001b[43m,\u001b[49m\n\u001b[1;32m   2214\u001b[0m \u001b[43m    \u001b[49m\u001b[43mdirect\u001b[49m\u001b[38;5;241;43m=\u001b[39;49m\u001b[43mdirect\u001b[49m\u001b[43m,\u001b[49m\n\u001b[1;32m   2215\u001b[0m \u001b[43m    \u001b[49m\u001b[43mlocal_worker\u001b[49m\u001b[38;5;241;43m=\u001b[39;49m\u001b[43mlocal_worker\u001b[49m\u001b[43m,\u001b[49m\n\u001b[1;32m   2216\u001b[0m \u001b[43m    \u001b[49m\u001b[43masynchronous\u001b[49m\u001b[38;5;241;43m=\u001b[39;49m\u001b[43masynchronous\u001b[49m\u001b[43m,\u001b[49m\n\u001b[1;32m   2217\u001b[0m \u001b[43m\u001b[49m\u001b[43m)\u001b[49m\n",
      "File \u001b[0;32m/srv/conda/envs/notebook/lib/python3.10/site-packages/distributed/utils.py:338\u001b[0m, in \u001b[0;36mSyncMethodMixin.sync\u001b[0;34m(self, func, asynchronous, callback_timeout, *args, **kwargs)\u001b[0m\n\u001b[1;32m    336\u001b[0m     \u001b[38;5;28;01mreturn\u001b[39;00m future\n\u001b[1;32m    337\u001b[0m \u001b[38;5;28;01melse\u001b[39;00m:\n\u001b[0;32m--> 338\u001b[0m     \u001b[38;5;28;01mreturn\u001b[39;00m \u001b[43msync\u001b[49m\u001b[43m(\u001b[49m\n\u001b[1;32m    339\u001b[0m \u001b[43m        \u001b[49m\u001b[38;5;28;43mself\u001b[39;49m\u001b[38;5;241;43m.\u001b[39;49m\u001b[43mloop\u001b[49m\u001b[43m,\u001b[49m\u001b[43m \u001b[49m\u001b[43mfunc\u001b[49m\u001b[43m,\u001b[49m\u001b[43m \u001b[49m\u001b[38;5;241;43m*\u001b[39;49m\u001b[43margs\u001b[49m\u001b[43m,\u001b[49m\u001b[43m \u001b[49m\u001b[43mcallback_timeout\u001b[49m\u001b[38;5;241;43m=\u001b[39;49m\u001b[43mcallback_timeout\u001b[49m\u001b[43m,\u001b[49m\u001b[43m \u001b[49m\u001b[38;5;241;43m*\u001b[39;49m\u001b[38;5;241;43m*\u001b[39;49m\u001b[43mkwargs\u001b[49m\n\u001b[1;32m    340\u001b[0m \u001b[43m    \u001b[49m\u001b[43m)\u001b[49m\n",
      "File \u001b[0;32m/srv/conda/envs/notebook/lib/python3.10/site-packages/distributed/utils.py:401\u001b[0m, in \u001b[0;36msync\u001b[0;34m(loop, func, callback_timeout, *args, **kwargs)\u001b[0m\n\u001b[1;32m    399\u001b[0m \u001b[38;5;28;01melse\u001b[39;00m:\n\u001b[1;32m    400\u001b[0m     \u001b[38;5;28;01mwhile\u001b[39;00m \u001b[38;5;129;01mnot\u001b[39;00m e\u001b[38;5;241m.\u001b[39mis_set():\n\u001b[0;32m--> 401\u001b[0m         \u001b[43mwait\u001b[49m\u001b[43m(\u001b[49m\u001b[38;5;241;43m10\u001b[39;49m\u001b[43m)\u001b[49m\n\u001b[1;32m    403\u001b[0m \u001b[38;5;28;01mif\u001b[39;00m error:\n\u001b[1;32m    404\u001b[0m     typ, exc, tb \u001b[38;5;241m=\u001b[39m error\n",
      "File \u001b[0;32m/srv/conda/envs/notebook/lib/python3.10/site-packages/distributed/utils.py:390\u001b[0m, in \u001b[0;36msync.<locals>.wait\u001b[0;34m(timeout)\u001b[0m\n\u001b[1;32m    388\u001b[0m \u001b[38;5;28;01mdef\u001b[39;00m \u001b[38;5;21mwait\u001b[39m(timeout):\n\u001b[1;32m    389\u001b[0m     \u001b[38;5;28;01mtry\u001b[39;00m:\n\u001b[0;32m--> 390\u001b[0m         \u001b[38;5;28;01mreturn\u001b[39;00m \u001b[43me\u001b[49m\u001b[38;5;241;43m.\u001b[39;49m\u001b[43mwait\u001b[49m\u001b[43m(\u001b[49m\u001b[43mtimeout\u001b[49m\u001b[43m)\u001b[49m\n\u001b[1;32m    391\u001b[0m     \u001b[38;5;28;01mexcept\u001b[39;00m \u001b[38;5;167;01mKeyboardInterrupt\u001b[39;00m:\n\u001b[1;32m    392\u001b[0m         loop\u001b[38;5;241m.\u001b[39madd_callback(cancel)\n",
      "File \u001b[0;32m/srv/conda/envs/notebook/lib/python3.10/threading.py:607\u001b[0m, in \u001b[0;36mEvent.wait\u001b[0;34m(self, timeout)\u001b[0m\n\u001b[1;32m    605\u001b[0m signaled \u001b[38;5;241m=\u001b[39m \u001b[38;5;28mself\u001b[39m\u001b[38;5;241m.\u001b[39m_flag\n\u001b[1;32m    606\u001b[0m \u001b[38;5;28;01mif\u001b[39;00m \u001b[38;5;129;01mnot\u001b[39;00m signaled:\n\u001b[0;32m--> 607\u001b[0m     signaled \u001b[38;5;241m=\u001b[39m \u001b[38;5;28;43mself\u001b[39;49m\u001b[38;5;241;43m.\u001b[39;49m\u001b[43m_cond\u001b[49m\u001b[38;5;241;43m.\u001b[39;49m\u001b[43mwait\u001b[49m\u001b[43m(\u001b[49m\u001b[43mtimeout\u001b[49m\u001b[43m)\u001b[49m\n\u001b[1;32m    608\u001b[0m \u001b[38;5;28;01mreturn\u001b[39;00m signaled\n",
      "File \u001b[0;32m/srv/conda/envs/notebook/lib/python3.10/threading.py:324\u001b[0m, in \u001b[0;36mCondition.wait\u001b[0;34m(self, timeout)\u001b[0m\n\u001b[1;32m    322\u001b[0m \u001b[38;5;28;01melse\u001b[39;00m:\n\u001b[1;32m    323\u001b[0m     \u001b[38;5;28;01mif\u001b[39;00m timeout \u001b[38;5;241m>\u001b[39m \u001b[38;5;241m0\u001b[39m:\n\u001b[0;32m--> 324\u001b[0m         gotit \u001b[38;5;241m=\u001b[39m \u001b[43mwaiter\u001b[49m\u001b[38;5;241;43m.\u001b[39;49m\u001b[43macquire\u001b[49m\u001b[43m(\u001b[49m\u001b[38;5;28;43;01mTrue\u001b[39;49;00m\u001b[43m,\u001b[49m\u001b[43m \u001b[49m\u001b[43mtimeout\u001b[49m\u001b[43m)\u001b[49m\n\u001b[1;32m    325\u001b[0m     \u001b[38;5;28;01melse\u001b[39;00m:\n\u001b[1;32m    326\u001b[0m         gotit \u001b[38;5;241m=\u001b[39m waiter\u001b[38;5;241m.\u001b[39macquire(\u001b[38;5;28;01mFalse\u001b[39;00m)\n",
      "\u001b[0;31mKeyboardInterrupt\u001b[0m: "
     ]
    },
    {
     "name": "stderr",
     "output_type": "stream",
     "text": [
      "/srv/conda/envs/notebook/lib/python3.10/site-packages/dask_gateway/client.py:1014: RuntimeWarning: coroutine 'rpc.close_rpc' was never awaited\n",
      "  self.scheduler_comm.close_rpc()\n",
      "RuntimeWarning: Enable tracemalloc to get the object allocation traceback\n",
      "2022-10-12 22:53:59,644 - distributed.client - ERROR - argument of type 'NoneType' is not iterable\n",
      "Traceback (most recent call last):\n",
      "  File \"/srv/conda/envs/notebook/lib/python3.10/site-packages/distributed/comm/tcp.py\", line 223, in read\n",
      "    frames_nbytes = await stream.read_bytes(fmt_size)\n",
      "tornado.iostream.StreamClosedError: Stream is closed\n",
      "\n",
      "During handling of the above exception, another exception occurred:\n",
      "\n",
      "Traceback (most recent call last):\n",
      "  File \"/srv/conda/envs/notebook/lib/python3.10/site-packages/distributed/client.py\", line 1556, in _close\n",
      "    await asyncio.wait_for(asyncio.shield(handle_report_task), 0.1)\n",
      "  File \"/srv/conda/envs/notebook/lib/python3.10/asyncio/tasks.py\", line 445, in wait_for\n",
      "    return fut.result()\n",
      "  File \"/srv/conda/envs/notebook/lib/python3.10/site-packages/distributed/utils.py\", line 799, in wrapper\n",
      "    return await func(*args, **kwargs)\n",
      "  File \"/srv/conda/envs/notebook/lib/python3.10/site-packages/distributed/client.py\", line 1427, in _handle_report\n",
      "    msgs = await self.scheduler_comm.comm.read()\n",
      "  File \"/srv/conda/envs/notebook/lib/python3.10/site-packages/distributed/comm/tcp.py\", line 239, in read\n",
      "    convert_stream_closed_error(self, e)\n",
      "  File \"/srv/conda/envs/notebook/lib/python3.10/site-packages/distributed/comm/tcp.py\", line 140, in convert_stream_closed_error\n",
      "    if \"UNKNOWN_CA\" in exc.reason:\n",
      "TypeError: argument of type 'NoneType' is not iterable\n",
      "2022-10-12 22:53:59,645 - distributed.client - WARNING - Exception raised while closing clients\n",
      "Traceback (most recent call last):\n",
      "  File \"/srv/conda/envs/notebook/lib/python3.10/site-packages/distributed/comm/tcp.py\", line 223, in read\n",
      "    frames_nbytes = await stream.read_bytes(fmt_size)\n",
      "tornado.iostream.StreamClosedError: Stream is closed\n",
      "\n",
      "During handling of the above exception, another exception occurred:\n",
      "\n",
      "Traceback (most recent call last):\n",
      "  File \"/srv/conda/envs/notebook/lib/python3.10/site-packages/dask_gateway/client.py\", line 984, in _stop_internal\n",
      "    await self._stop_task\n",
      "  File \"/srv/conda/envs/notebook/lib/python3.10/site-packages/dask_gateway/client.py\", line 1016, in _stop_async\n",
      "    await client._close()\n",
      "  File \"/srv/conda/envs/notebook/lib/python3.10/site-packages/distributed/client.py\", line 1556, in _close\n",
      "    await asyncio.wait_for(asyncio.shield(handle_report_task), 0.1)\n",
      "  File \"/srv/conda/envs/notebook/lib/python3.10/asyncio/tasks.py\", line 445, in wait_for\n",
      "    return fut.result()\n",
      "  File \"/srv/conda/envs/notebook/lib/python3.10/site-packages/distributed/utils.py\", line 799, in wrapper\n",
      "    return await func(*args, **kwargs)\n",
      "  File \"/srv/conda/envs/notebook/lib/python3.10/site-packages/distributed/client.py\", line 1427, in _handle_report\n",
      "    msgs = await self.scheduler_comm.comm.read()\n",
      "  File \"/srv/conda/envs/notebook/lib/python3.10/site-packages/distributed/comm/tcp.py\", line 239, in read\n",
      "    convert_stream_closed_error(self, e)\n",
      "  File \"/srv/conda/envs/notebook/lib/python3.10/site-packages/distributed/comm/tcp.py\", line 140, in convert_stream_closed_error\n",
      "    if \"UNKNOWN_CA\" in exc.reason:\n",
      "TypeError: argument of type 'NoneType' is not iterable\n",
      "2022-10-12 22:53:59,647 - distributed.client - ERROR - Exception raised while shutting down cluster prod.56f301a5a39d427198d2c7b36515d5d5\n",
      "Traceback (most recent call last):\n",
      "  File \"/srv/conda/envs/notebook/lib/python3.10/site-packages/dask_gateway/client.py\", line 993, in _stop_internal\n",
      "    await self.gateway._stop_cluster(self.name)\n",
      "  File \"/srv/conda/envs/notebook/lib/python3.10/site-packages/dask_gateway/client.py\", line 654, in _stop_cluster\n",
      "    await self._request(\"DELETE\", url)\n",
      "  File \"/srv/conda/envs/notebook/lib/python3.10/site-packages/dask_gateway/client.py\", line 397, in _request\n",
      "    resp = await session.request(method, url, json=json, **self._request_kwargs)\n",
      "  File \"/srv/conda/envs/notebook/lib/python3.10/site-packages/aiohttp/client.py\", line 535, in _request\n",
      "    conn = await self._connector.connect(\n",
      "  File \"/srv/conda/envs/notebook/lib/python3.10/site-packages/aiohttp/connector.py\", line 542, in connect\n",
      "    proto = await self._create_connection(req, traces, timeout)\n",
      "  File \"/srv/conda/envs/notebook/lib/python3.10/site-packages/aiohttp/connector.py\", line 907, in _create_connection\n",
      "    _, proto = await self._create_direct_connection(req, traces, timeout)\n",
      "  File \"/srv/conda/envs/notebook/lib/python3.10/site-packages/aiohttp/connector.py\", line 1154, in _create_direct_connection\n",
      "    hosts = await asyncio.shield(host_resolved)\n",
      "  File \"/srv/conda/envs/notebook/lib/python3.10/site-packages/aiohttp/connector.py\", line 880, in _resolve_host\n",
      "    addrs = await self._resolver.resolve(host, port, family=self._family)\n",
      "  File \"/srv/conda/envs/notebook/lib/python3.10/site-packages/aiohttp/resolver.py\", line 33, in resolve\n",
      "    infos = await self._loop.getaddrinfo(\n",
      "  File \"/srv/conda/envs/notebook/lib/python3.10/asyncio/base_events.py\", line 860, in getaddrinfo\n",
      "    return await self.run_in_executor(\n",
      "  File \"/srv/conda/envs/notebook/lib/python3.10/asyncio/base_events.py\", line 818, in run_in_executor\n",
      "    executor.submit(func, *args), loop=self)\n",
      "  File \"/srv/conda/envs/notebook/lib/python3.10/concurrent/futures/thread.py\", line 167, in submit\n",
      "    raise RuntimeError('cannot schedule new futures after shutdown')\n",
      "RuntimeError: cannot schedule new futures after shutdown\n"
     ]
    }
   ],
   "source": [
    "# compute predictions\n",
    "scene_preds = rfc.predict(is_veg.to_dask_array())\n",
    "scene_preds = scene_preds.compute()"
   ]
  },
  {
   "cell_type": "code",
   "execution_count": null,
   "id": "0f4f2bcb-e198-442a-8ff1-577b9cb1b296",
   "metadata": {},
   "outputs": [],
   "source": [
    "# ---------------------------------------\n",
    "# retrieve pixel #s for vegetation pixels\n",
    "veg_index = is_veg_index.compute()"
   ]
  },
  {
   "cell_type": "code",
   "execution_count": null,
   "id": "dc2033cb-47d0-4ab8-912a-f84df863fa14",
   "metadata": {},
   "outputs": [],
   "source": [
    "# ---------------------------------------\n",
    "# recover pixel indices for iceplant classifications\n",
    "preds_df = pd.DataFrame(scene_preds, \n",
    "                         columns=['is_iceplant'], \n",
    "                         index = veg_index)\n",
    "is_iceplant_index = preds_df[preds_df.is_iceplant == 1].index.to_numpy()\n",
    "non_iceplant_index = preds_df[preds_df.is_iceplant == 0].index.to_numpy()\n",
    "\n",
    "# ---------------------------------------\n",
    "# reconstruct indices into image\n",
    "indices = [non_iceplant_index,\n",
    "           is_iceplant_index]\n",
    "values = [0,    # values assigned to pixels from each index\n",
    "          1]\n",
    "\n",
    "reconstruct = rm.indices_to_image(y_n,x_n, indices, values, back_value=0)\n",
    "\n",
    "# ---------------------------------------\n",
    "# save raster \n",
    "filename = 'S_preds_' + itemid +'.tif'\n",
    "\n",
    "with rasterio.open(\n",
    "    os.path.join(os.getcwd(),'temp',filename),  # file path\n",
    "    'w',           # w = write\n",
    "    driver = 'GTiff', # format\n",
    "    height = y_n, \n",
    "    width = x_n,\n",
    "    count = 1,  # number of raster bands in the dataset\n",
    "    dtype = rasterio.uint8,\n",
    "    crs = raster.rio.crs,\n",
    "#    transform = raster.rio.transform(),\n",
    "    transform = Affine(*item.properties['proj:transform'][0:6]),\n",
    ") as dst:\n",
    "    dst.write(reconstruct.astype(rasterio.uint8), 1)\n",
    "# ---------------------------------------\n",
    "print('FINISHED: ', itemid , '\\n')"
   ]
  },
  {
   "cell_type": "code",
   "execution_count": null,
   "id": "b851995c-531f-472c-867a-38606fe42de9",
   "metadata": {},
   "outputs": [],
   "source": []
  }
 ],
 "metadata": {
  "kernelspec": {
   "display_name": "Python 3 (ipykernel)",
   "language": "python",
   "name": "python3"
  },
  "language_info": {
   "codemirror_mode": {
    "name": "ipython",
    "version": 3
   },
   "file_extension": ".py",
   "mimetype": "text/x-python",
   "name": "python",
   "nbconvert_exporter": "python",
   "pygments_lexer": "ipython3",
   "version": "3.10.6"
  }
 },
 "nbformat": 4,
 "nbformat_minor": 5
}
